Workbook
Name ID: #REF!
Name prod: #REF!
Name Producenci: #REF!
Name Producent: #REF!
Name z_nazwa: 'BAZA NAZW'!$B:$B
Name z_prod: 'BAZA NAZW'!$A:$A

Sheet PBTO
A1: Nr wpisu do rejestru przedsiębiorstw wykonujących działalość w zakresie potwierdzania sprawności technicznej sprzętu do stosowania środków ochrony roślin: | G1: Protokół badania technicznego opryskiwacza | O1: Urządzenie opryskiwacza | Q1: Rodzaj wyposażenia | U1: Przedmiot badań | AC1: Ocena przy wyłączonym napędzie | AE1: Ocena przy włączonym napędzie | AG1: Uwagi i zalecenia
J2: Nr | K2: 96 | M2: /20 | AC2: wada | AD2: w normie | AE2: wada | AF2: w normie
A3: 18/11/4835 | G3: Opryskiwacz wprowadzony do obrotu | K3: Opryskiwacz będący w eksploatacji* | O3: 2.6 Belka polowa opryskiwacza | Q3: Szerokość [m] | U3: 2.6.1 | V3: Stabilność i stan techniczny
G4: (*- niepotrzebne skreślić) | Q4: 10 | U4: 2.6.2 | V4: Składanie i stan techniczny
G5: Numer seryjny lub ewidencyjny opryskiwacza: | K5: ew. | L5: 864 | M5: fab. | N5: - | U5: 2.6.3 | V5: Blokada belki polowej, działanie
G6: Typ opryskiwacza: | L6: polowy | N6: sadowniczy | U6: 2.6.4 | V6: Regulacja wysokości, działanie
A7: Pieczęć podmiotu przeprowadzającego badanie | G7: Rodzaj opryskiwacza: | U7: 2.6.5 | V7: Położenie względem powierzchni
U8: 2.6.6 | V8: Ustawienie rozpylaczy
A9: Imię i nazwisko lub nazwa posiadacza opryskiwacza | U9: 2.6.7 | V9: Mechanizm odchylania, działanie
A10: Wojciech Skiba | U10: 2.6.8 | V10: Mechanizm tłumienia wahań belki, działanie
A11: Adres: | G11: Nazwa: | K11: P-146/1 | U11: 2.6.9 | V11: Zawory przeciwkroplowe, działanie
A12: Trzęsówka 205 | G12: Producent: | K12: Dziekan | O12: 2.7 Sekcje (ciągnikowy lub samobieżny sadowniczy) | Q12: Liczba sekcji | U12: 2.7.1 | V12: Ustawienie rozpylaczy
A13: 36-306 Trzęsówka | G13: Rok produkcji: | K13: 2008 | Q13: - | U13: 2.7.2 | V13: Zawory przeciwkroplowe, działanie
A14: Pesel lub NIP: | C14: 80072317756 | G14: Data ostatniego badania: | K14: 42980 | O14: 2.8 Rozpylacze | Q14: Cechy i oznaczenia | U14: 2.8.1 | V14: Stan techniczny, typ, rozmiar, kąt, materiał
O15: zainstalowane na opryskiwaczu ciągnikowym i samobieżnym polowym | U15: 2.8.2 | V15: Filtry rozpylaczy, typ, rozmiar
U16: 2.8.3 | V16: Sprawdzenie dystrybucji cieczy jedną z metod; lp. 2.8.3.1, 2.8.3.2 albo 2.8.3.3
A17: 1. Badanie ogólne opryskiwacza | Q17: POL VP 110-03
A18: Przedmiot badań | K18: Wynik badań | M18: Uwagi i zalecenia
K19: wada | L19: w normie | X19: 8.0 | Y19: % rynienek
A20: 1.1 | C20: Kompletność, stan techniczny osłon części wirujących | V20: 2.8.3.2 Pomiar współczynnika nierównomierności rozkładu poprzecznego na elektronicznym stole rowkowym [%]
A21: 1.2 | C21: Pewność mocowania
A22: 1.3 | C22: Stan zużycia części - zespołów | V22: ____________
A23: 1.4 | C23: Szczelność zbiornika | V23: (współczynnik zmienności nie większy niż 10%)
A24: 1.5 | C24: Czystość | V24: 2.8.3.3 Jednoczesny pomiar natężenia wypływu cieczy z rozpylaczy - odchylenie od nominalnej wartości (nie więcej niż 10% dla rozpylacza)
A25: 2. Badanie stanu technicznego poszczególnych części i urządzeń opryskiwacza
A26: Urządzenie opryskiwacza | C26: Rodzaj wyposażenia | G26: Przedmiot badań | J26: Ocena przy wyłączonym napędzie | L26: Ocena przy włączonym napędzie | N26: Uwagi i zalecenia | Q26: przy optymalnej wartości ciśnienia
J27: wada | K27: w normie | L27: wada | M27: w normie | U27: 2.8.4 | V27: Pomiar spadku wartości ciśnienia**
A28: 2.1 Pompa | G28: 2.1.1 | H28: Szczelność | O28: 2.9 Rozpylacze | Q28: Cechy i oznaczenie firmowe | U28: 2.9.1 | V28: Stan techniczny, typ, rozmiar, kąt, materiał
A29: Natężenie wypływu [dm3/min] | G29: 2.1.2 | H29: Smarowanie | O29: zainstalowane na opryskiwaczu sadowniczym | U29: 2.9.2 | V29: Jednoczesny pomiar natężenia wypływu cieczy z rozpylaczy - odchylenie od nominalnej wartości (nie więcej niż 15%) oraz L≠P (≤10%)
G30: 2.1.3 | H30: Tłumienie pulsacji
A31: PP100 | C31: typ: | G31: 2.1.4 | H31: Wydajność | O31: 2.10 Wentylator | Q31: typ: | U31: 2.10.1 | V31: Stan techniczny i urządzenia sterujące
G32: 2.1.5 | H32: Zawór bezpieczeństwa | O32: Różnice wskazań pomiędzy badanym manometrem a wzorcowym [2.3.4]
C33: Pojemność zbiornika [l] | G33: 2.2.1 | H33: Pokrywa otworu wlewowego | O33: Wskazania manometru wzorcowego [MPa] | AA33: Odchyenie wskazań [%]
C34: 400 | G34: 2.2.2 | H34: System uniemożliwiający nad- lub podciśnienie | O34: manometr badany | U34: manometr wzorcowy
G35: 2.2.3 | H35: Mieszanie cieczy | O35: 0.1 | U35: 0.1 | AA35: 0
G36: 2.2.4 | H36: Wstępne filtrowanie, w tym sito wlewowe | O36: 0.3 | U36: 0.3 | AA36: 0
G37: 2.2.5 | H37: Wskaźnik poziomu cieczy | O37: 0.5 | U37: 0.5 | AA37: 0
G38: 2.2.6 | H38: Zawór spustowy zbiornika | O38: Pomiar natężenia wypływu cieczy z rozpylaczy w opryskiwaczu polowym lub sadowniczym [2.8.3.3 lub 2.9.2]
G39: 2.2.7 | H39: Przepłukiwanie, stan tech. i działanie | O39: Nr rozpylacza | T39: 1 | V39: 2 | W39: 3 | X39: 4 | Y39: 5 | Z39: 6 | AA39: 7 | AC39: 8 | AD39: 9 | AE39: 10 | AF39: 11 | AG39: 12
G40: 2.2.8 | H40: Rozwadniacz, stan tech. i działanie | O40: Odchyłka od wart. nominalnej [%]
...

Sheet BAZA NAZW
A1: Agrola | B1: P-147
A2: Agromechanika KRANJ | B2: P-146
A3: Agromet Mogilno | B3: P-081
A4: Akpil | B4: Pilmet
A5: Alman | B5: Składak
A6: Amazone | B6: Hardi
A7: Biardzki | B7: P-182/5
A8: Blanchard | B8: Vogel&Noot
A9: Bogaerts Greenhouse Logistics | B9: P-125
A10: Demarol | B10: P-059
A11: Dziekan | B11: Ranger 2500
A12: Elektromet | B12: Dziekan
... A36: Renal | B36: P-068
A37: Rol-Oprysk Busko Zdrój
A38: Rosenbauer | B38: Rau
A39: Sieger | B39: P-143/2
A40: Składak | B40: AGP-400
A41: SKotarek | B41: P-027/4
A42: Stalmech | B42: P-146/2
A43: Stanimpex | B43: P-146/3
A44: Starzyński Prostyń | B44: P-080
A45: Tad-Len | B45: Kaspol
A46: Tecnoma | B46: P-155
A47: UNIGREEN | B47: Krukowiak
A48: Vanjet AB | B48: P-126
A49: Vogel&Noot | B49: P-143
... A56: ZPSiUD Gostyń | B56: Promar
B57: Agromechanika KRANJ
B58: Agrola 400/12
B59: P-329
B60: P027
B61: Agromet Mogilno
B62: Pilmet 412
B63: P155/4
B64: P-027/5
B65: Pilmet 412LM
B66: Pilmet 312
B67: Pilmet 1615
B68: P066
... B163: P081

Sheet PZ
A1: =#REF! -> #REF! | B1: =#REF! -> #REF! | C1: =MONTH(#REF!)&" "&YEAR(#REF!) -> #REF! | H1: 1 2017 | I1: styczeń | J1: =COUNTIF(C1:C1200,"1 2017") -> 0 | L1: =MOJAFUNKCJA(H1,$B$1:$C$1200,0) -> #NAME?
A2: =#REF! -> #REF! | B2: =#REF! -> #REF! | C2: =MONTH(#REF!)&" "&YEAR(#REF!) -> #REF! | H2: 2 2017 | I2: luty | J2: =COUNTIF(C1:C1200,"2 2017") -> 0 | L2: =MOJAFUNKCJA(H2,$B$1:$C$1200,0) -> #NAME? | M2: =RIGHT(PZ!L2,LEN(PZ!L2)-1) -> #NAME?
A3: =#REF! -> #REF! | B3: =#REF! -> #REF! | C3: =MONTH(#REF!)&" "&YEAR(#REF!) -> #REF! | H3: 3 2017 | I3: marzec | J3: =COUNTIF(C1:C1200,"3 2017") -> 0 | L3: =MOJAFUNKCJA(H3,$B$1:$C$1200,0) -> #NAME? | M3: =RIGHT(PZ!L3,LEN(PZ!L3)-1) -> #NAME?
A4: =#REF! -> #REF! | B4: =#REF! -> #REF! | C4: =MONTH(#REF!)&" "&YEAR(#REF!) -> #REF! | H4: 4 2017 | I4: kwiecień | J4: =COUNTIF(C1:C1200,"4 2017") -> 0 | L4: =MOJAFUNKCJA(H4,$B$1:$C$1200,0) -> #NAME? | M4: =RIGHT(PZ!L4,LEN(PZ!L4)-1) -> #NAME?
A5: =#REF! -> #REF! | B5: =#REF! -> #REF! | C5: =MONTH(#REF!)&" "&YEAR(#REF!) -> #REF! | H5: 5 2017 | I5: maj | J5: =COUNTIF(C1:C1200,"5 2017") -> 0 | L5: =MOJAFUNKCJA(H5,$B$1:$C$1200,0) -> #NAME? | M5: =RIGHT(PZ!L5,LEN(PZ!L5)-1) -> #NAME?
A6: =#REF! -> #REF! | B6: =#REF! -> #REF! | C6: =MONTH(#REF!)&" "&YEAR(#REF!) -> #REF! | H6: 6 0217 | I6: czerwiec | J6: =COUNTIF(C1:C1200,"6 2017") -> 0 | L6: =MOJAFUNKCJA("6 2017",A1:C1200,0) -> #NAME? | M6: =RIGHT(PZ!L6,LEN(PZ!L6)-1) -> #NAME?
A7: =#REF! -> #REF! | B7: =#REF! -> #REF! | C7: =MONTH(#REF!)&" "&YEAR(#REF!) -> #REF! | H7: 7 2017 | I7: lipiec | J7: =COUNTIF(C1:C1200,"7 2017") -> 0 | L7: =MOJAFUNKCJA(H7,$B$1:$C$1200,0) -> #NAME? | M7: =RIGHT(PZ!L7,LEN(PZ!L7)-1) -> #NAME?
A8: =#REF! -> #REF! | B8: =#REF! -> #REF! | C8: =MONTH(#REF!)&" "&YEAR(#REF!) -> #REF! | H8: 8 2017 | I8: sierpień | J8: =COUNTIF(C1:C1200,"8 2017") -> 0 | L8: =MOJAFUNKCJA(H8,$B$1:$C$1200,0) -> #NAME? | M8: =RIGHT(PZ!L8,LEN(PZ!L8)-1) -> #NAME?
A9: =#REF! -> #REF! | B9: =#REF! -> #REF! | C9: =MONTH(#REF!)&" "&YEAR(#REF!) -> #REF! | H9: 9 2017 | I9: wrzesień | J9: =COUNTIF(C1:C1200,"9 2017") -> 0 | L9: =MOJAFUNKCJA(H9,$B$1:$C$1200,0) -> #NAME? | M9: =RIGHT(PZ!L9,LEN(PZ!L9)-1) -> #NAME?
A10: =#REF! -> #REF! | B10: =#REF! -> #REF! | C10: =MONTH(#REF!)&" "&YEAR(#REF!) -> #REF! | H10: 10 2017 | I10: październik | J10: =COUNTIF(C1:C1200,"10 2017") -> 0 | L10: =MOJAFUNKCJA(H10,$B$1:$C$1200,0) -> #NAME? | M10: =RIGHT(PZ!L10,LEN(PZ!L10)-1) -> #NAME?
A11: =#REF! -> #REF! | B11: =#REF! -> #REF! | C11: =MONTH(#REF!)&" "&YEAR(#REF!) -> #REF! | H11: 11 2017 | I11: listopad | J11: =COUNTIF(C1:C1200,"11 2017") -> 0 | L11: =MOJAFUNKCJA(H11,$B$1:$C$1200,0) -> #NAME? | M11: =RIGHT(PZ!L11,LEN(PZ!L11)-1) -> #NAME?
A12: =#REF! -> #REF! | B12: =#REF! -> #REF! | C12: =MONTH(#REF!)&" "&YEAR(#REF!) -> #REF! | H12: 12 2017 | I12: grudzień | J12: =COUNTIF(C1:C1200,"12 2017") -> 0 | L12: =MOJAFUNKCJA(H12,$B$1:$C$1200,0) -> #NAME? | M12: =RIGHT(PZ!L12,LEN(PZ!L12)-1) -> #NAME?
A13: =#REF! -> #REF! | B13: =#REF! -> #REF! | C13: =MONTH(#REF!)&" "&YEAR(#REF!) -> #REF!
A14: =#REF! -> #REF! | B14: =#REF! -> #REF! | C14: =MONTH(#REF!)&" "&YEAR(#REF!) -> #REF!
A15: =#REF! -> #REF! | B15: =#REF! -> #REF! | C15: =MONTH(#REF!)&" "&YEAR(#REF!) -> #REF!
A16: =#REF! -> #REF! | B16: =#REF! -> #REF! | C16: =MONTH(#REF!)&" "&YEAR(#REF!) -> #REF!
A17: =#REF! -> #REF! | B17: =#REF! -> #REF! | C17: =MONTH(#REF!)&" "&YEAR(#REF!) -> #REF!
A18: =#REF! -> #REF! | B18: =#REF! -> #REF! | C18: =MONTH(#REF!)&" "&YEAR(#REF!) -> #REF!
A19: =#REF! -> #REF! | B19: =#REF! -> #REF! | C19: =MONTH(#REF!)&" "&YEAR(#REF!) -> #REF!
A20: =#REF! -> #REF! | B20: =#REF! -> #REF! | C20: =MONTH(#REF!)&" "&YEAR(#REF!) -> #REF!
A21: =#REF! -> #REF! | B21: =#REF! -> #REF! | C21: =MONTH(#REF!)&" "&YEAR(#REF!) -> #REF!
A22: =#REF! -> #REF! | B22: =#REF! -> #REF! | C22: =MONTH(#REF!)&" "&YEAR(#REF!) -> #REF!
A23: =#REF! -> #REF! | B23: =#REF! -> #REF! | C23: =MONTH(#REF!)&" "&YEAR(#REF!) -> #REF!
A24: =#REF! -> #REF! | B24: =#REF! -> #REF! | C24: =MONTH(#REF!)&" "&YEAR(#REF!) -> #REF!
... A1200: =#REF! -> #REF! | B1200: =#REF! -> #REF! | C1200: =MONTH(#REF!)&" "&YEAR(#REF!) -> #REF!

Sheet Arkusz1
E1: STYCZEŃ
E2: LUTY
E3: MARZEC
E4: KWIECIEŃ
E5: MAJ
E6: CZERWIEC
E7: LIPIEC
E8: SIERPIEŃ
E9: WRZESIEŃ
E10: PAŹDZIERNIK
E11: LISTOPAD
E12: GRUDZIEŃ
